Workbook
Name ctl_scenario: Sensitivity!$E$5
Name ctl_tornado: Sensitivity!$E$6
Name ctl_ovr_1: Sensitivity!$E$7
Name ctl_ovr_2: Sensitivity!$E$8
Name ctl_ovr_3: Sensitivity!$E$9
Name ctl_ovr_4: Sensitivity!$E$10

Sheet Cover
B2: Example Co - three-pillar impact model (TEMPLATE: replace every input)
B4: Company | C4: Example Co (illustrative)
B5: Currency / units | C5: EURm
B6: Timeline | C6: 2020-2024 actuals, 2025-2029 projection
B7: Objective | C7: revenue growth
B8: Prepared by | C8: Team name
B9: As of | C9: 2026-01-01
B11: How to read | C11: Inputs -> Calculations -> Outputs / Bridge / Sensitivity; Checks must show 0 errors.
B12: Colours | C12: Blue on yellow = typed input (Inputs, Actuals). Orange = Sensitivity control. Green = headline output. Everything else is a formula.
B13: Grades | C13: Source reliability A (reliable) - F (cannot judge); information credibility 1 (confirmed) - 6 (cannot judge). Every input carries one.
B14: Scenarios | C14: Low/Base/High move every ranged input to its pessimistic/optimistic end (polarity aware).
B15: Recalculate | C15: Excel recalculates on open. Data Tables: Formulas > Calculation Options > Automatic.
B16: Independent check | C16: python scripts/check_model.py <this file> (must pass every check)
B17: History | C17: 3 reported series on Actuals; growth, CAGR, quartiles and margins in Calculations section 0. 2 inputs take their value from history (cust0, cust_g). Baseline growth is checked against the historical band (Checks).
B19: Headline: the case objectives in 2029 (base case = do nothing)
B20: KPI | C20: Base case | D20: With strategies | E20: Change | F20: Better?
B21: Revenue (EURm) | C21: =Objectives!E5 | D21: =Objectives!F5 | E21: =Objectives!G5 | F21: =Objectives!J5
B22: EBITDA (EURm) | C22: =Objectives!E6 | D22: =Objectives!F6 | E22: =Objectives!G6 | F22: =Objectives!J6
B23: EBITDA margin (pp) | C23: =Objectives!E7 | D23: =Objectives!F7 | E23: =Objectives!G7 | F23: =Objectives!J7
B24: Valuation (secondary) | C24: =Calculations!$E$172 | D24: NPV in EURm; see Outputs. Breakdown through the consulting frameworks: Frameworks sheet.

Sheet Objectives
B1: Case objectives - how the strategies move them
B2: Base case = do nothing. Change = with strategies minus base case, in 2029 and summed over 2025-2029. All cells link to Calculations section 10.
B4: Objective | C4: KPI | D4: Unit | E4: Base case 2029 | F4: With strategies 2029 | G4: Change 2029 | H4: Change % | I4: Cumulative change 2025-2029 | J4: Better?
B5: Profit: Revenue growth | C5: Revenue | D5: EURm | E5: =Calculations!$E$209 | F5: =Calculations!$E$210 | G5: =Calculations!$E$211 | H5: =IF(E5=0,"n/a",G5/ABS(E5)) | I5: =Calculations!$E$212 | J5: =IF(G5=0,"no change",IF(G5>0,"better","worse"))
B6: Profit: Profitability | C6: EBITDA | D6: EURm | E6: =Calculations!$E$213 | F6: =Calculations!$E$214 | G6: =Calculations!$E$215 | H6: =IF(E6=0,"n/a",G6/ABS(E6)) | I6: =Calculations!$E$216 | J6: =IF(G6=0,"no change",IF(G6>0,"better","worse"))
B7: Profit: Profitability | C7: EBITDA margin | D7: pp | E7: =Calculations!$E$217 | F7: =Calculations!$E$218 | G7: =Calculations!$E$219 | J7: =IF(G7=0,"no change",IF(G7>0,"better","worse"))
B9: Contribution of each strategy to the change in 2029 (vs base case)
B10: Pillar | C10: Strategy | D10: Revenue (EURm) | E10: EBITDA (EURm)
B11: Pillar A | C11: Initiative A1 | D11: =Calculations!P125 | E11: =Calculations!P149
B12: Pillar B | C12: Initiative B1 | D12: =Calculations!P126 | E12: =Calculations!P150
B13: Pillar C | C13: Initiative C1 | D13: =Calculations!P127 | E13: =Calculations!P151
B14: Total | D14: =SUM(D11:D13) | E14: =SUM(E11:E13)
B16: By pillar (change in 2029 vs base case)
B17: Pillar | D17: Revenue (EURm) | E17: EBITDA (EURm)
B18: Pillar A | D18: =D11 | E18: =E11
B19: Pillar B | D19: =D12 | E19: =E12
B20: Pillar C | D20: =D13 | E20: =E13
B21: Total | D21: =SUM(D18:D20) | E21: =SUM(E18:E20)

Sheet Frameworks
B1: The impact through the consulting frameworks
B2: Each view splits the same change vs the base case (2029; revenue summed over 2025-2029); every view adds up to the strategy total (Checks).
B4: 1. Triple bottom line (Elkington): profit, planet and people by pillar
B5: Rows are the team's pillars; columns are the case objectives.
B6: Category | C6: Cumulative incremental revenue (EURm) | D6: Profit: Revenue 2029 (EURm) | E6: Profit: EBITDA 2029 (EURm) | F6: Strategies
B7: Pillar A | C7: =SUM(Calculations!L125:P125) | D7: =Calculations!P125 | E7: =Calculations!P149 | F7: Initiative A1
B8: Pillar B | C8: =SUM(Calculations!L126:P126) | D8: =Calculations!P126 | E8: =Calculations!P150 | F8: Initiative B1
B9: Pillar C | C9: =SUM(Calculations!L127:P127) | D9: =Calculations!P127 | E9: =Calculations!P151 | F9: Initiative C1
B10: Total | C10: =SUM(C7:C9) | D10: =SUM(D7:D9) | E10: =SUM(E7:E9)
B13: 2. Profitability tree: where the change in EBITDA comes from (2029)
B14: Profit = (volume x price) x margin - costs. Each strategy's effect, split by the lever it pulls.
B15: Lever | C15: EBITDA change 2029 (EURm) | D15: Strategies
B16: Revenue: more volume (customers, visits, occupancy), after variable costs | C16: =Calculations!P125*Calculations!$E$49+Calculations!P126*Calculations!$E$49 | D16: Initiative A1, Initiative B1
B17: Revenue: higher price or spend per unit, after variable costs | C17: =Calculations!P127*Calculations!$E$49 | D17: Initiative C1
B18: Revenue: new streams (volume x price of a new offer), after variable costs | C18: =0 | D18: -
B19: Cost: savings (cost avoided) | C19: =0 | D19: -
B20: Cost: operating cost added by the strategies | C20: =-Calculations!P137-Calculations!P138 | D20: Initiative A1, Initiative C1
B21: Total | C21: =SUM(C16:C20)
B24: 3. Ansoff matrix: growth vector
B25: Where the growth comes from: existing or new products and markets; efficiency moves cost, not growth.
B26: Category | C26: Cumulative incremental revenue (EURm) | D26: Profit: Revenue 2029 (EURm) | E26: Profit: EBITDA 2029 (EURm) | F26: Strategies
B27: Existing products, existing markets (selling more into today's market) | C27: =SUM(Calculations!L125:P125)+SUM(Calculations!L126:P126)+SUM(Calculations!L127:P127) | D27: =Calculations!P125+Calculations!P126+Calculations!P127 | E27: =Calculations!P149+Calculations!P150+Calculations!P151 | F27: Initiative A1, Initiative B1, Initiative C1
B28: New products, existing markets (product development) | C28: =0 | D28: =0 | E28: =0 | F28: -
B29: Existing products, new markets (market development) | C29: =0 | D29: =0 | E29: =0 | F29: -
B30: New products, new markets (diversification) | C30: =0 | D30: =0 | E30: =0 | F30: -
B31: Efficiency (cost and resources) | C31: =0 | D31: =0 | E31: =0 | F31: -
B32: Total | C32: =SUM(C27:C31) | D32: =SUM(D27:D31) | E32: =SUM(E27:E31)
B35: 4. Marketing mix (4Ps)
B36: Which marketing lever each strategy pulls.
B37: Category | C37: Cumulative incremental revenue (EURm) | D37: Profit: Revenue 2029 (EURm) | E37: Profit: EBITDA 2029 (EURm) | F37: Strategies
B38: Price | C38: =SUM(Calculations!L127:P127) | D38: =Calculations!P127 | E38: =Calculations!P151 | F38: Initiative C1
B39: Product | C39: =0 | D39: =0 | E39: =0 | F39: -
B40: Place (channel) | C40: =0 | D40: =0 | E40: =0 | F40: -
B41: Promotion | C41: =0 | D41: =0 | E41: =0 | F41: -
B42: Not a marketing-mix lever (cost, operations) | C42: =0 | D42: =0 | E42: =0 | F42: -
B43: Not tagged (set frameworks.<lens> on the initiative) | C43: =SUM(Calculations!L125:P125)+SUM(Calculations!L126:P126) | D43: =Calculations!P125+Calculations!P126 | E43: =Calculations!P149+Calculations!P150 | F43: Initiative A1, Initiative B1
B44: Total | C44: =SUM(C38:C43) | D44: =SUM(D38:D43) | E44: =SUM(E38:E43)
B47: 5. Value chain (Porter)
B48: Which activity of the business each strategy changes.
B49: Category | C49: Cumulative incremental revenue (EURm) | D49: Profit: Revenue 2029 (EURm) | E49: Profit: EBITDA 2029 (EURm) | F49: Strategies
...

Sheet Inputs
B1: Inputs - assumptions register
B2: Every number used by the model, once. Blue = typed input. Grade: source reliability A-F, information credibility 1-6 (A1 best).
A5: ID | B5: Input | C5: Unit | D5: Type | E5: Low | F5: Base | G5: High | H5: Polarity | I5: Source | J5: Date | K5: Link / database path | L5: Grade | M5: Benchmark low (p25) | N5: Benchmark median | O5: Benchmark high (p75) | P5: Benchmark source | Q5: Justification (if above p75) | R5: Used by | S5: Key | T5: Revision
B6: Baseline drivers
A7: 1 | B7: Customers, base year | C7: m | D7: actual | E7: =Actuals!$K$8 | F7: =Actuals!$K$8 | G7: =Actuals!$K$8 | H7: 1 | I7: History: last reported value of Customers (reported) 2020-2024 (live link to the Actuals sheet). Data: ILLUSTRATIVE - replace (annual report KPIs / case pack) | J7: 2026-01-01 | K7: - | L7: F6 | R7: leaf customers | S7: cust0
A8: 2 | B8: Baseline growth in customers | C8: % | D8: assumption | E8: 0 | F8: =Calculations!$E$25 | G8: 0.02 | H8: 1 | I8: History: CAGR of Customers (reported) 2020-2024 (live link to the Actuals sheet). Data: ILLUSTRATIVE - replace (annual report KPIs / case pack) | J8: 2026-01-01 | K8: - | L8: F6 | R8: leaf customers | S8: cust_g
A9: 3 | B9: Purchases per customer per year | C9: x | D9: actual | E9: 8 | F9: 8 | G9: 8 | H9: 1 | I9: ILLUSTRATIVE - replace (loyalty data) | J9: 2026-01-01 | K9: - | L9: F6 | R9: leaf freq | S9: freq0
A10: 4 | B10: Average ticket, base year | C10: EUR | D10: actual | E10: 25 | F10: 25 | G10: 25 | H10: 1 | I10: Derived: revenue / (customers x purchases) | J10: 2026-01-01 | K10: - | L10: F6 | R10: leaf ticket | S10: ticket0
A11: 5 | B11: Price inflation | C11: % | D11: assumption | E11: 0.015 | F11: 0.02 | G11: 0.03 | H11: 1 | I11: ILLUSTRATIVE - replace (IMF WEO PCPIPCH) | J11: 2026-01-01 | K11: - | L11: F6 | R11: leaf ticket | S11: infl
B12: Market ceilings
A13: 6 | B13: Ceiling: addressable customers | C13: m | D13: actual | E13: 4 | F13: 4 | G13: 4 | H13: 1 | I13: ILLUSTRATIVE - replace (national statistics office population in catchment) | J13: 2026-01-01 | K13: - | L13: F6 | R13: leaf customers | S13: market
A14: 7 | B14: Growth in addressable customers | C14: % | D14: assumption | E14: 0 | F14: 0.005 | G14: 0.01 | H14: 1 | I14: ILLUSTRATIVE - replace (Eurostat population projections) | J14: 2026-01-01 | K14: - | L14: F6 | R14: leaf customers | S14: market_g
B15: Revenue scaling
A16: 8 | B16: Unit conversion: EUR to EURm with customers in millions | C16: x | D16: conversion | E16: 1 | F16: 1 | G16: 1 | H16: 1 | I16: Arithmetic: m customers x purchases x EUR = EURm | J16: 2026-01-01 | K16: - | L16: A1 | S16: to_m
B17: Initiatives - Pillar A
A18: 9 | B18: Pillar A: peak uplift in customers | C18: % | D18: uplift | E18: 0.02 | F18: 0.04 | G18: 0.06 | H18: 1 | I18: ILLUSTRATIVE - replace | J18: 2026-01-01 | K18: - | L18: F6 | M18: 0.02 | N18: 0.04 | O18: 0.06 | P18: ILLUSTRATIVE - build the reference class (Factiva cases) (p25 / median / p75) | R18: a1 | S18: a_up
A19: 10 | B19: Annual erosion of initiative effects | C19: % | D19: assumption | E19: 0 | F19: 0.03 | G19: 0.06 | H19: 1 | I19: ILLUSTRATIVE - replace | J19: 2026-01-01 | K19: - | L19: F6 | R19: a1, b1, c1 | S19: decay
A20: 11 | B20: Bass p | C20: x | D20: assumption | E20: 0.02 | F20: 0.03 | G20: 0.06 | H20: 1 | I20: Sultan, Farley & Lehmann (1990) JMR: mean p = 0.03 (replace with analogous launch) | J20: 1990-02-01 | K20: JMR 27(1) | L20: B2 | R20: a1, b1 | S20: bass_p
A21: 12 | B21: Bass q | C21: x | D21: assumption | E21: 0.25 | F21: 0.38 | G21: 0.5 | H21: 1 | I21: Sultan, Farley & Lehmann (1990) JMR: mean q = 0.38 | J21: 1990-02-01 | K21: JMR 27(1) | L21: B2 | R21: a1, b1 | S21: bass_q
A22: 13 | B22: Launch year: Initiative A1 | C22: year | D22: plan | E22: 2025 | F22: 2025 | G22: 2025 | H22: 1 | I22: Team implementation plan | J22: 2026-01-01 | K22: Strategy deck / roadmap | L22: A1 | R22: a1 | S22: a1_launch
B23: Initiatives - Pillar B
A24: 14 | B24: Pillar B: peak uplift in purchase frequency | C24: % | D24: uplift | E24: 0.02 | F24: 0.03 | G24: 0.05 | H24: 1 | I24: ILLUSTRATIVE - replace | J24: 2026-01-01 | K24: - | L24: F6 | M24: 0.01 | N24: 0.03 | O24: 0.06 | P24: ILLUSTRATIVE - Scopus meta-analysis (p25 / median / p75) | R24: b1 | S24: b_up
A25: 15 | B25: Launch year: Initiative B1 | C25: year | D25: plan | E25: 2025 | F25: 2025 | G25: 2025 | H25: 1 | I25: Team implementation plan | J25: 2026-01-01 | K25: Strategy deck / roadmap | L25: A1 | R25: b1 | S25: b1_launch
B26: Initiatives - Pillar C
A27: 16 | B27: Pillar C: peak uplift in average ticket | C27: % | D27: uplift | E27: 0.01 | F27: 0.02 | G27: 0.04 | H27: 1 | I27: ILLUSTRATIVE - replace | J27: 2026-01-01 | K27: - | L27: F6 | M27: 0.01 | N27: 0.025 | O27: 0.05 | P27: ILLUSTRATIVE - Factiva / Euromonitor (p25 / median / p75) | R27: c1 | S27: c_up
A28: 17 | B28: Pillar C: years to full effect (linear ramp) | C28: years | D28: assumption | E28: 1 | F28: 2 | G28: 3 | H28: 1 | I28: ILLUSTRATIVE - replace (roll-out plan vs comparable launches) | J28: 2026-01-01 | K28: - | L28: F6 | R28: c1 | S28: c_ytp
A29: 18 | B29: Launch year: Initiative C1 | C29: year | D29: plan | E29: 2026 | F29: 2026 | G29: 2026 | H29: 1 | I29: Team implementation plan | J29: 2026-01-01 | K29: Strategy deck / roadmap | L29: A1 | R29: c1 | S29: c1_launch
B30: Costs
A31: 19 | B31: Pillar A: annual cost | C31: EURm | D31: cost | E31: 0.2 | F31: 0.3 | G31: 0.4 | H31: -1 | I31: ILLUSTRATIVE - replace | J31: 2026-01-01 | K31: - | L31: F6 | R31: a1 | S31: a_opex
A32: 20 | B32: Pillar B: launch investment | C32: EURm | D32: cost | E32: 0.5 | F32: 0.8 | G32: 1.2 | H32: -1 | I32: ILLUSTRATIVE - replace | J32: 2026-01-01 | K32: - | L32: F6 | R32: b1 | S32: b_capex
A33: 21 | B33: Pillar C: annual cost | C33: EURm | D33: cost | E33: 0.1 | F33: 0.2 | G33: 0.3 | H33: -1 | I33: ILLUSTRATIVE - replace | J33: 2026-01-01 | K33: - | L33: F6 | R33: c1 | S33: c_opex
B34: Finance & WACC
A35: 22 | B35: Contribution margin on incremental revenue | C35: % | D35: assumption | E35: 0.25 | F35: 0.35 | G35: 0.45 | H35: 1 | I35: ILLUSTRATIVE - replace ((revenue - variable costs) / revenue from the P&L) | J35: 2026-01-01 | K35: - | L35: F6 | R35: finance | S35: margin
A36: 23 | B36: Corporate tax rate | C36: % | D36: assumption | E36: 0.25 | F36: 0.25 | G36: 0.28 | H36: 1 | I36: ILLUSTRATIVE - replace (national tax law) | J36: 2026-01-01 | K36: - | L36: F6 | R36: finance | S36: tax
A37: 24 | B37: Risk-free rate | C37: % | D37: assumption | E37: 0.025 | F37: 0.03 | G37: 0.035 | H37: 1 | I37: ILLUSTRATIVE - replace (10y government yield, Bloomberg) | J37: 2026-01-01 | K37: - | L37: F6 | R37: finance | S37: rf
A38: 25 | B38: Levered beta | C38: x | D38: assumption | E38: 0.8 | F38: 1 | G38: 1.2 | H38: 1 | I38: ILLUSTRATIVE - replace (peer median, Bloomberg/WRDS) | J38: 2026-01-01 | K38: - | L38: F6 | R38: finance | S38: beta
A39: 26 | B39: Equity risk premium | C39: % | D39: assumption | E39: 0.04 | F39: 0.045 | G39: 0.05 | H39: 1 | I39: ILLUSTRATIVE - replace (Damodaran ctryprem) | J39: 2026-01-01 | K39: - | L39: F6 | R39: finance | S39: erp
A40: 27 | B40: Pre-tax cost of debt | C40: % | D40: assumption | E40: 0.04 | F40: 0.05 | G40: 0.06 | H40: 1 | I40: ILLUSTRATIVE - replace | J40: 2026-01-01 | K40: - | L40: F6 | R40: finance | S40: kd
A41: 28 | B41: Debt weight D/(D+E) | C41: % | D41: assumption | E41: 0.2 | F41: 0.3 | G41: 0.4 | H41: 1 | I41: ILLUSTRATIVE - replace | J41: 2026-01-01 | K41: - | L41: F6 | R41: finance | S41: wd
A42: 29 | B42: Terminal growth of incremental FCF after the horizon | C42: % | D42: assumption | E42: -0.05 | F42: -0.02 | G42: 0.01 | H42: 1 | I42: Modelling choice: effects fade 2%/yr after the horizon (low: 5% fade as competitors copy; high: +1%); Gordon growth model | J42: 2026-01-01 | K42: Damodaran, Investment Valuation (3rd ed.), ch. 12 | L42: C3 | R42: finance | S42: tv_g
...

Sheet Actuals
B1: Actuals - reported financials
B2: Base year comes from reported accounts, never a press summary.
A5: ID | B5: Item | C5: Unit | D5: Source | E5: Grade | F5: Date | G5: =Calculations!G3 | H5: =Calculations!H3 | I5: =Calculations!I3 | J5: =Calculations!J3 | K5: =Calculations!K3 | L5: =Calculations!L3 | M5: =Calculations!M3 | N5: =Calculations!N3 | ... P5: =Calculations!P3
A6: rev | B6: Revenue (reported) | C6: EURm | D6: ILLUSTRATIVE - replace with SABI/Orbis or the annual report | E6: F6 | F6: 2026-01-01 | G6: 88.9 | H6: 91.5 | I6: 94.3 | J6: 97.1 | K6: 100
A7: ebitda_h | B7: EBITDA (reported) | C7: EURm | D7: ILLUSTRATIVE - replace with SABI/Orbis or the annual report | E7: F6 | F7: 2026-01-01 | G7: 10.2 | H7: 10.8 | I7: 11.5 | J7: 12.1 | K7: 13
A8: cust_h | B8: Customers (reported) | C8: m | D8: ILLUSTRATIVE - replace (annual report KPIs / case pack) | E8: F6 | F8: 2026-01-01 | G8: 0.48 | H8: 0.486 | I8: 0.49 | J8: 0.495 | K8: 0.5

Sheet Calculations
B1: Calculations
B2: No typed numbers on this sheet: every cell is a formula fed by Inputs, Actuals or the Sensitivity controls.
B3: Period | G3: =G4&IF(G4<=Inputs!$F$46,"A","E") | H3: =H4&IF(H4<=Inputs!$F$46,"A","E") | I3: =I4&IF(I4<=Inputs!$F$46,"A","E") | J3: =J4&IF(J4<=Inputs!$F$46,"A","E") | K3: =K4&IF(K4<=Inputs!$F$46,"A","E") | L3: =L4&IF(L4<=Inputs!$F$46,"A","E") | M3: =M4&IF(M4<=Inputs!$F$46,"A","E") | N3: =N4&IF(N4<=Inputs!$F$46,"A","E") | ... P3: =P4&IF(P4<=Inputs!$F$46,"A","E")
B4: Year | G4: =Inputs!$F$45 | H4: =G4+1 | I4: =H4+1 | J4: =I4+1 | K4: =J4+1 | L4: =K4+1 | M4: =L4+1 | N4: =M4+1 | O4: =N4+1 | P4: =O4+1
B5: Years from base year (t) | G5: =G4-Inputs!$F$46 | H5: =H4-Inputs!$F$46 | I5: =I4-Inputs!$F$46 | J5: =J4-Inputs!$F$46 | K5: =K4-Inputs!$F$46 | L5: =L4-Inputs!$F$46 | M5: =M4-Inputs!$F$46 | N5: =N4-Inputs!$F$46 | ... P5: =P4-Inputs!$F$46
B7: 0. Reported history: growth, CAGR, quartiles and margins (feeds history-linked inputs)
A8: rev | B8: Revenue (reported): YoY growth | C8: % | H8: =Actuals!H6/Actuals!G6-1 | I8: =Actuals!I6/Actuals!H6-1 | J8: =Actuals!J6/Actuals!I6-1 | K8: =Actuals!K6/Actuals!J6-1
B9: Revenue (reported): CAGR 2020-2024 | C9: % | E9: =(Actuals!K6/Actuals!G6)^(1/(K$4-G$4))-1
B10: Revenue (reported): median YoY growth | C10: % | E10: =MEDIAN(H8:K8)
B11: Revenue (reported): YoY growth, lower percentile | C11: % | E11: =PERCENTILE(H8:K8,Inputs!$F$51)
B12: Revenue (reported): YoY growth, upper percentile | C12: % | E12: =PERCENTILE(H8:K8,Inputs!$F$52)
A14: ebitda_h | B14: EBITDA (reported): YoY growth | C14: % | H14: =Actuals!H7/Actuals!G7-1 | I14: =Actuals!I7/Actuals!H7-1 | J14: =Actuals!J7/Actuals!I7-1 | K14: =Actuals!K7/Actuals!J7-1
B15: EBITDA (reported): CAGR 2020-2024 | C15: % | E15: =(Actuals!K7/Actuals!G7)^(1/(K$4-G$4))-1
B16: EBITDA (reported): median YoY growth | C16: % | E16: =MEDIAN(H14:K14)
B17: EBITDA (reported): YoY growth, lower percentile | C17: % | E17: =PERCENTILE(H14:K14,Inputs!$F$51)
B18: EBITDA (reported): YoY growth, upper percentile | C18: % | E18: =PERCENTILE(H14:K14,Inputs!$F$52)
A19: ebitda_h | B19: EBITDA (reported): % of revenue | C19: % | G19: =Actuals!G7/Actuals!G6 | H19: =Actuals!H7/Actuals!H6 | I19: =Actuals!I7/Actuals!I6 | J19: =Actuals!J7/Actuals!J6 | K19: =Actuals!K7/Actuals!K6
B20: EBITDA (reported): median % of revenue | C20: % | E20: =MEDIAN(G19:K19)
B21: EBITDA (reported): % of revenue, lower percentile | C21: % | E21: =PERCENTILE(G19:K19,Inputs!$F$51)
B22: EBITDA (reported): % of revenue, upper percentile | C22: % | E22: =PERCENTILE(G19:K19,Inputs!$F$52)
A24: cust_h | B24: Customers (reported): YoY growth | C24: % | H24: =Actuals!H8/Actuals!G8-1 | I24: =Actuals!I8/Actuals!H8-1 | J24: =Actuals!J8/Actuals!I8-1 | K24: =Actuals!K8/Actuals!J8-1
B25: Customers (reported): CAGR 2020-2024 | C25: % | E25: =(Actuals!K8/Actuals!G8)^(1/(K$4-G$4))-1
B26: Customers (reported): median YoY growth | C26: % | E26: =MEDIAN(H24:K24)
B27: Customers (reported): YoY growth, lower percentile | C27: % | E27: =PERCENTILE(H24:K24,Inputs!$F$51)
B28: Customers (reported): YoY growth, upper percentile | C28: % | E28: =PERCENTILE(H24:K24,Inputs!$F$52)
B30: 1. Live inputs (Base case unless a scenario, tornado or sensitivity switch is set)
A31: cust0 | B31: Customers, base year | C31: m | D31: Inputs row 7 | E31: =Inputs!$F$7
A32: cust_g | B32: Baseline growth in customers | C32: % | D32: Inputs row 8 | E32: =IF(Sensitivity!$E$6=Inputs!$A$8,Inputs!$G$8,IF(Sensitivity!$E$6=-Inputs!$A$8,Inputs!$E$8,CHOOSE(Sensitivity!$E$5,IF(Inputs!$H$8>0,Inputs!$E$8,Inputs!$G$8),Inputs!$F$8,IF(Inputs!$H$8>0,Inputs!$G$8,Inputs!$E$8))))
A33: market | B33: Ceiling: addressable customers | C33: m | D33: Inputs row 13 | E33: =Inputs!$F$13
A34: market_g | B34: Growth in addressable customers | C34: % | D34: Inputs row 14 | E34: =IF(Sensitivity!$E$6=Inputs!$A$14,Inputs!$G$14,IF(Sensitivity!$E$6=-Inputs!$A$14,Inputs!$E$14,CHOOSE(Sensitivity!$E$5,IF(Inputs!$H$14>0,Inputs!$E$14,Inputs!$G$14),Inputs!$F$14,IF(Inputs!$H$14>0,Inputs!$G$14,Inputs!$E$14))))
A35: freq0 | B35: Purchases per customer per year | C35: x | D35: Inputs row 9 | E35: =Inputs!$F$9
A36: ticket0 | B36: Average ticket, base year | C36: EUR | D36: Inputs row 10 | E36: =Inputs!$F$10
A37: infl | B37: Price inflation | C37: % | D37: Inputs row 11 | E37: =IF(Sensitivity!$E$6=Inputs!$A$11,Inputs!$G$11,IF(Sensitivity!$E$6=-Inputs!$A$11,Inputs!$E$11,CHOOSE(Sensitivity!$E$5,IF(Inputs!$H$11>0,Inputs!$E$11,Inputs!$G$11),Inputs!$F$11,IF(Inputs!$H$11>0,Inputs!$G$11,Inputs!$E$11))))
A38: to_m | B38: Unit conversion: EUR to EURm with customers in millions | C38: x | D38: Inputs row 16 | E38: =Inputs!$F$16
A39: a_up | B39: Pillar A: peak uplift in customers | C39: % | D39: Inputs row 18 | E39: =IF(Sensitivity!$E$6=Inputs!$A$18,Inputs!$G$18,IF(Sensitivity!$E$6=-Inputs!$A$18,Inputs!$E$18,CHOOSE(Sensitivity!$E$5,IF(Inputs!$H$18>0,Inputs!$E$18,Inputs!$G$18),Inputs!$F$18,IF(Inputs!$H$18>0,Inputs!$G$18,Inputs!$E$18))))
A40: b_up | B40: Pillar B: peak uplift in purchase frequency | C40: % | D40: Inputs row 24 | E40: =IF(Sensitivity!$E$6=Inputs!$A$24,Inputs!$G$24,IF(Sensitivity!$E$6=-Inputs!$A$24,Inputs!$E$24,CHOOSE(Sensitivity!$E$5,IF(Inputs!$H$24>0,Inputs!$E$24,Inputs!$G$24),Inputs!$F$24,IF(Inputs!$H$24>0,Inputs!$G$24,Inputs!$E$24))))
A41: c_up | B41: Pillar C: peak uplift in average ticket | C41: % | D41: Inputs row 27 | E41: =IF(ISNUMBER(Sensitivity!$E$7),Sensitivity!$E$7,IF(Sensitivity!$E$6=Inputs!$A$27,Inputs!$G$27,IF(Sensitivity!$E$6=-Inputs!$A$27,Inputs!$E$27,CHOOSE(Sensitivity!$E$5,IF(Inputs!$H$27>0,Inputs!$E$27,Inputs!$G$27),Inputs!$F$27,IF(Inputs!$H$27>0,Inputs!$G$27,Inputs!$E$27)))))
A42: decay | B42: Annual erosion of initiative effects | C42: % | D42: Inputs row 19 | E42: =IF(Sensitivity!$E$6=Inputs!$A$19,Inputs!$G$19,IF(Sensitivity!$E$6=-Inputs!$A$19,Inputs!$E$19,CHOOSE(Sensitivity!$E$5,IF(Inputs!$H$19>0,Inputs!$E$19,Inputs!$G$19),Inputs!$F$19,IF(Inputs!$H$19>0,Inputs!$G$19,Inputs!$E$19))))
A43: bass_p | B43: Bass p | C43: x | D43: Inputs row 20 | E43: =IF(ISNUMBER(Sensitivity!$E$10),Sensitivity!$E$10,IF(Sensitivity!$E$6=Inputs!$A$20,Inputs!$G$20,IF(Sensitivity!$E$6=-Inputs!$A$20,Inputs!$E$20,CHOOSE(Sensitivity!$E$5,IF(Inputs!$H$20>0,Inputs!$E$20,Inputs!$G$20),Inputs!$F$20,IF(Inputs!$H$20>0,Inputs!$G$20,Inputs!$E$20)))))
A44: bass_q | B44: Bass q | C44: x | D44: Inputs row 21 | E44: =IF(Sensitivity!$E$6=Inputs!$A$21,Inputs!$G$21,IF(Sensitivity!$E$6=-Inputs!$A$21,Inputs!$E$21,CHOOSE(Sensitivity!$E$5,IF(Inputs!$H$21>0,Inputs!$E$21,Inputs!$G$21),Inputs!$F$21,IF(Inputs!$H$21>0,Inputs!$G$21,Inputs!$E$21))))
...

Sheet Outputs
B1: Outputs - Example Co - three-pillar impact model (TEMPLATE: replace every input)
B2: Currency: EURm. All cells link to Calculations.
B3: Period | G3: =Calculations!G3 | H3: =Calculations!H3 | I3: =Calculations!I3 | J3: =Calculations!J3 | K3: =Calculations!K3 | L3: =Calculations!L3 | M3: =Calculations!M3 | N3: =Calculations!N3 | ... P3: =Calculations!P3
B4: Year | G4: =Calculations!G4 | H4: =Calculations!H4 | I4: =Calculations!I4 | J4: =Calculations!J4 | K4: =Calculations!K4 | L4: =Calculations!L4 | M4: =Calculations!M4 | N4: =Calculations!N4 | ... P4: =Calculations!P4
B6: Headline results (base case unless Sensitivity switches are set)
B7: NPV of strategy at WACC | C7: EURm | E7: =Calculations!$E$172
B8: of which PV of terminal value | C8: EURm | E8: =Calculations!$E$171
B9: Horizon-only NPV (no terminal value) | C9: EURm | E9: =Calculations!$E$169
B10: IRR | C10: % | E10: =Calculations!$E$173
B11: Payback (years after base year) | C11: years | E11: =Calculations!$E$174
B12: WACC | C12: % | E12: =Calculations!$E$74
B13: Incremental revenue in 2029 | C13: EURm | E13: =Calculations!$E$176
B14: Incremental EBIT in 2029 | C14: EURm | E14: =Calculations!$E$177
B15: Cumulative incremental revenue | C15: EURm | E15: =Calculations!$E$175
B16: Baseline revenue in 2029 | C16: EURm | E16: =Calculations!$E$188
B17: Target revenue in 2029 | C17: EURm | E17: =Calculations!$E$189
B19: Base case vs history
B20: Reported revenue CAGR 2020-2024 | C20: % | E20: =Calculations!$E$9
B21: Reported revenue: median YoY growth | C21: % | E21: =Calculations!$E$10
B22: Reported revenue: YoY growth, lower percentile | C22: % | E22: =Calculations!$E$11
B23: Reported revenue: YoY growth, upper percentile | C23: % | E23: =Calculations!$E$12
B24: Baseline revenue CAGR 2024-2029 (do nothing) | C24: % | E24: =Calculations!$E$194
B25: EBITDA (reported): median % of revenue | C25: % | E25: =Calculations!$E$20
B27: Revenue path
B28: Reported revenue (actuals) | C28: EURm | G28: =Calculations!G120 | H28: =Calculations!H120 | I28: =Calculations!I120 | J28: =Calculations!J120 | K28: =Calculations!K120
B29: Baseline revenue (do nothing) | C29: EURm | K29: =Calculations!K117 | L29: =Calculations!L117 | M29: =Calculations!M117 | N29: =Calculations!N117 | O29: =Calculations!O117 | P29: =Calculations!P117
B30: Target revenue (with strategy) | C30: EURm | K30: =Calculations!K118 | L30: =Calculations!L118 | M30: =Calculations!M118 | N30: =Calculations!N118 | O30: =Calculations!O118 | P30: =Calculations!P118
B32: Incremental revenue by pillar
B33: Incremental revenue: Pillar A | C33: EURm | L33: =Calculations!L131 | M33: =Calculations!M131 | N33: =Calculations!N131 | O33: =Calculations!O131 | P33: =Calculations!P131
B34: Incremental revenue: Pillar B | C34: EURm | L34: =Calculations!L132 | M34: =Calculations!M132 | N34: =Calculations!N132 | O34: =Calculations!O132 | P34: =Calculations!P132
B35: Incremental revenue: Pillar C | C35: EURm | L35: =Calculations!L133 | M35: =Calculations!M133 | N35: =Calculations!N133 | O35: =Calculations!O133 | P35: =Calculations!P133
B36: Total incremental revenue | C36: EURm | L36: =SUM(L33:L35) | M36: =SUM(M33:M35) | N36: =SUM(N33:N35) | O36: =SUM(O33:O35) | P36: =SUM(P33:P35)
B38: Incremental revenue by initiative
B39: Incremental revenue: Initiative A1 | C39: EURm | L39: =Calculations!L125 | M39: =Calculations!M125 | N39: =Calculations!N125 | O39: =Calculations!O125 | P39: =Calculations!P125
B40: Incremental revenue: Initiative B1 | C40: EURm | L40: =Calculations!L126 | M40: =Calculations!M126 | N40: =Calculations!N126 | O40: =Calculations!O126 | P40: =Calculations!P126
B41: Incremental revenue: Initiative C1 | C41: EURm | L41: =Calculations!L127 | M41: =Calculations!M127 | N41: =Calculations!N127 | O41: =Calculations!O127 | P41: =Calculations!P127
B42: Total incremental revenue | C42: EURm | L42: =SUM(L39:L41) | M42: =SUM(M39:M41) | N42: =SUM(N39:N41) | O42: =SUM(O39:O41) | P42: =SUM(P39:P41)
B44: Incremental EBIT by pillar (revenue x margin + cost savings - opex)
B45: Incremental EBIT: Pillar A | C45: EURm | L45: =Calculations!L153 | M45: =Calculations!M153 | N45: =Calculations!N153 | O45: =Calculations!O153 | P45: =Calculations!P153
B46: Incremental EBIT: Pillar B | C46: EURm | L46: =Calculations!L154 | M46: =Calculations!M154 | N46: =Calculations!N154 | O46: =Calculations!O154 | P46: =Calculations!P154
...

Sheet Bridge
B1: Revenue bridge 2029: baseline to target (EURm)
B2: One-slide impact bridge. Columns D-G drive the waterfall chart.
B4: Step | C4: Value | D4: Invisible base | E4: Increase | F4: Decrease | G4: Level | H4: Running total
B5: Baseline revenue 2029 (do nothing) | C5: =Calculations!P117 | G5: =C5 | H5: =C5
B6: Pillar A: Initiative A1 | C6: =Calculations!P125 | D6: =IF(C6>=0,H5,H5+C6) | E6: =MAX(C6,0) | F6: =MAX(-C6,0) | H6: =H5+C6
B7: Pillar B: Initiative B1 | C7: =Calculations!P126 | D7: =IF(C7>=0,H6,H6+C7) | E7: =MAX(C7,0) | F7: =MAX(-C7,0) | H7: =H6+C7
B8: Pillar C: Initiative C1 | C8: =Calculations!P127 | D8: =IF(C8>=0,H7,H7+C8) | E8: =MAX(C8,0) | F8: =MAX(-C8,0) | H8: =H7+C8
B9: Target revenue 2029 (with strategy) | C9: =Calculations!P118 | G9: =C9 | H9: =C9
B11: Incremental EBIT bridge 2029 by initiative (EURm)
B12: Do nothing (no incremental EBIT) | C12: =0 | G12: =C12 | H12: =C12
B13: Pillar A: Initiative A1 | C13: =Calculations!P149 | D13: =IF(C13>=0,H12,H12+C13) | E13: =MAX(C13,0) | F13: =MAX(-C13,0) | H13: =H12+C13
B14: Pillar B: Initiative B1 | C14: =Calculations!P150 | D14: =IF(C14>=0,H13,H13+C14) | E14: =MAX(C14,0) | F14: =MAX(-C14,0) | H14: =H13+C14
B15: Pillar C: Initiative C1 | C15: =Calculations!P151 | D15: =IF(C15>=0,H14,H14+C15) | E15: =MAX(C15,0) | F15: =MAX(-C15,0) | H15: =H14+C15
B16: Incremental EBIT 2029 (with strategy) | C16: =Calculations!P160 | G16: =C16 | H16: =C16

Sheet Sensitivity
B1: Sensitivity - scenarios, tornado, two-way tables
B2: Live Excel Data Tables (Data > What-If). Leave the orange controls at Base / 0 / blank.
B4: Controls
B5: Scenario switch (1 = Low, 2 = Base, 3 = High) | E5: 2
B6: Tornado selector (0 = off; set by the tornado Data Tables) | E6: 0
B7: Override for two-way table: Pillar C: peak uplift in average ticket (leave blank)
B8: Override for two-way table: Contribution margin on incremental revenue (leave blank)
B9: Override for two-way table: Terminal growth of incremental FCF after the horizon (leave blank)
B10: Override for two-way table: Bass p (leave blank)
B13: Scenarios: Low / Base / High (every ranged input moves to its pessimistic / optimistic end)
B14: Scenario | C14: Switch | D14: NPV | E14: Incr. revenue 2029 | F14: Incr. EBIT 2029 | G14: Cumulative incr. revenue
B15: Live (current switches) | D15: =Calculations!$E$172 | E15: =Calculations!$E$176 | F15: =Calculations!$E$177 | G15: =Calculations!$E$175
B16: Low | C16: 1
B17: Base | C17: 2
B18: High | C18: 3
B21: Tornado: NPV with each input at its low and high value, others at base
B22: Input | C22: Selector (low) | D22: NPV at low | E22: Selector (high) | F22: NPV at high | G22: Base NPV | H22: Delta at low | I22: Delta at high | J22: Swing | K22: Rank | L22: Sort key
B23: Live NPV | D23: =Calculations!$E$172 | F23: =Calculations!$E$172
B24: =Inputs!$B$8 | C24: =-Inputs!$A$8 | E24: =Inputs!$A$8 | G24: =Calculations!$E$172 | H24: =D24-G24 | I24: =F24-G24 | J24: =ABS(F24-D24) | K24: =RANK(L24,$L$24:$L$43) | L24: =J24+ROWS($J$24:J24)*Inputs!$F$50
B25: =Inputs!$B$11 | C25: =-Inputs!$A$11 | E25: =Inputs!$A$11 | G25: =Calculations!$E$172 | H25: =D25-G25 | I25: =F25-G25 | J25: =ABS(F25-D25) | K25: =RANK(L25,$L$24:$L$43) | L25: =J25+ROWS($J$24:J25)*Inputs!$F$50
B26: =Inputs!$B$18 | C26: =-Inputs!$A$18 | E26: =Inputs!$A$18 | G26: =Calculations!$E$172 | H26: =D26-G26 | I26: =F26-G26 | J26: =ABS(F26-D26) | K26: =RANK(L26,$L$24:$L$43) | L26: =J26+ROWS($J$24:J26)*Inputs!$F$50
B27: =Inputs!$B$19 | C27: =-Inputs!$A$19 | E27: =Inputs!$A$19 | G27: =Calculations!$E$172 | H27: =D27-G27 | I27: =F27-G27 | J27: =ABS(F27-D27) | K27: =RANK(L27,$L$24:$L$43) | L27: =J27+ROWS($J$24:J27)*Inputs!$F$50
B28: =Inputs!$B$20 | C28: =-Inputs!$A$20 | E28: =Inputs!$A$20 | G28: =Calculations!$E$172 | H28: =D28-G28 | I28: =F28-G28 | J28: =ABS(F28-D28) | K28: =RANK(L28,$L$24:$L$43) | L28: =J28+ROWS($J$24:J28)*Inputs!$F$50
B29: =Inputs!$B$21 | C29: =-Inputs!$A$21 | E29: =Inputs!$A$21 | G29: =Calculations!$E$172 | H29: =D29-G29 | I29: =F29-G29 | J29: =ABS(F29-D29) | K29: =RANK(L29,$L$24:$L$43) | L29: =J29+ROWS($J$24:J29)*Inputs!$F$50
B30: =Inputs!$B$24 | C30: =-Inputs!$A$24 | E30: =Inputs!$A$24 | G30: =Calculations!$E$172 | H30: =D30-G30 | I30: =F30-G30 | J30: =ABS(F30-D30) | K30: =RANK(L30,$L$24:$L$43) | L30: =J30+ROWS($J$24:J30)*Inputs!$F$50
B31: =Inputs!$B$27 | C31: =-Inputs!$A$27 | E31: =Inputs!$A$27 | G31: =Calculations!$E$172 | H31: =D31-G31 | I31: =F31-G31 | J31: =ABS(F31-D31) | K31: =RANK(L31,$L$24:$L$43) | L31: =J31+ROWS($J$24:J31)*Inputs!$F$50
B32: =Inputs!$B$28 | C32: =-Inputs!$A$28 | E32: =Inputs!$A$28 | G32: =Calculations!$E$172 | H32: =D32-G32 | I32: =F32-G32 | J32: =ABS(F32-D32) | K32: =RANK(L32,$L$24:$L$43) | L32: =J32+ROWS($J$24:J32)*Inputs!$F$50
B33: =Inputs!$B$31 | C33: =-Inputs!$A$31 | E33: =Inputs!$A$31 | G33: =Calculations!$E$172 | H33: =D33-G33 | I33: =F33-G33 | J33: =ABS(F33-D33) | K33: =RANK(L33,$L$24:$L$43) | L33: =J33+ROWS($J$24:J33)*Inputs!$F$50
B34: =Inputs!$B$32 | C34: =-Inputs!$A$32 | E34: =Inputs!$A$32 | G34: =Calculations!$E$172 | H34: =D34-G34 | I34: =F34-G34 | J34: =ABS(F34-D34) | K34: =RANK(L34,$L$24:$L$43) | L34: =J34+ROWS($J$24:J34)*Inputs!$F$50
B35: =Inputs!$B$33 | C35: =-Inputs!$A$33 | E35: =Inputs!$A$33 | G35: =Calculations!$E$172 | H35: =D35-G35 | I35: =F35-G35 | J35: =ABS(F35-D35) | K35: =RANK(L35,$L$24:$L$43) | L35: =J35+ROWS($J$24:J35)*Inputs!$F$50
B36: =Inputs!$B$35 | C36: =-Inputs!$A$35 | E36: =Inputs!$A$35 | G36: =Calculations!$E$172 | H36: =D36-G36 | I36: =F36-G36 | J36: =ABS(F36-D36) | K36: =RANK(L36,$L$24:$L$43) | L36: =J36+ROWS($J$24:J36)*Inputs!$F$50
B37: =Inputs!$B$36 | C37: =-Inputs!$A$36 | E37: =Inputs!$A$36 | G37: =Calculations!$E$172 | H37: =D37-G37 | I37: =F37-G37 | J37: =ABS(F37-D37) | K37: =RANK(L37,$L$24:$L$43) | L37: =J37+ROWS($J$24:J37)*Inputs!$F$50
B38: =Inputs!$B$37 | C38: =-Inputs!$A$37 | E38: =Inputs!$A$37 | G38: =Calculations!$E$172 | H38: =D38-G38 | I38: =F38-G38 | J38: =ABS(F38-D38) | K38: =RANK(L38,$L$24:$L$43) | L38: =J38+ROWS($J$24:J38)*Inputs!$F$50
B39: =Inputs!$B$38 | C39: =-Inputs!$A$38 | E39: =Inputs!$A$38 | G39: =Calculations!$E$172 | H39: =D39-G39 | I39: =F39-G39 | J39: =ABS(F39-D39) | K39: =RANK(L39,$L$24:$L$43) | L39: =J39+ROWS($J$24:J39)*Inputs!$F$50
B40: =Inputs!$B$39 | C40: =-Inputs!$A$39 | E40: =Inputs!$A$39 | G40: =Calculations!$E$172 | H40: =D40-G40 | I40: =F40-G40 | J40: =ABS(F40-D40) | K40: =RANK(L40,$L$24:$L$43) | L40: =J40+ROWS($J$24:J40)*Inputs!$F$50
B41: =Inputs!$B$40 | C41: =-Inputs!$A$40 | E41: =Inputs!$A$40 | G41: =Calculations!$E$172 | H41: =D41-G41 | I41: =F41-G41 | J41: =ABS(F41-D41) | K41: =RANK(L41,$L$24:$L$43) | L41: =J41+ROWS($J$24:J41)*Inputs!$F$50
B42: =Inputs!$B$41 | C42: =-Inputs!$A$41 | E42: =Inputs!$A$41 | G42: =Calculations!$E$172 | H42: =D42-G42 | I42: =F42-G42 | J42: =ABS(F42-D42) | K42: =RANK(L42,$L$24:$L$43) | L42: =J42+ROWS($J$24:J42)*Inputs!$F$50
B43: =Inputs!$B$42 | C43: =-Inputs!$A$42 | E43: =Inputs!$A$42 | G43: =Calculations!$E$172 | H43: =D43-G43 | I43: =F43-G43 | J43: =ABS(F43-D43) | K43: =RANK(L43,$L$24:$L$43) | L43: =J43+ROWS($J$24:J43)*Inputs!$F$50
B46: Tornado chart data: top 10 inputs by swing
B47: Rank | C47: Input | D47: Delta at low | E47: Delta at high
...

Sheet Checks
B1: Checks
B2: Each check reads OK or ERROR. Total errors must be 0 before handover. Then run scripts/check_model.py (the independent judge).
B3: Period | G3: =Calculations!G3 | H3: =Calculations!H3 | I3: =Calculations!I3 | J3: =Calculations!J3 | K3: =Calculations!K3 | L3: =Calculations!L3 | M3: =Calculations!M3 | N3: =Calculations!N3 | ... P3: =Calculations!P3
B4: Year | G4: =Calculations!G4 | H4: =Calculations!H4 | I4: =Calculations!I4 | J4: =Calculations!J4 | K4: =Calculations!K4 | L4: =Calculations!L4 | M4: =Calculations!M4 | N4: =Calculations!N4 | ... P4: =Calculations!P4
B6: Total errors (must be 0) | E6: =COUNTIF(E9:E39,"ERROR")
B8: Check | C8: Value | D8: Limit | E8: Result
B9: Baseline calibration: model base-year revenue vs reported (2024) | C9: =ABS(Calculations!$E$190/Calculations!$E$191-1) | D9: =Inputs!$F$48 | E9: =IF(C9<=D9,"OK","ERROR")
B10: Initiatives add up to stream incremental revenue (abs. difference) | C10: =MAX(L10:P10) | D10: =Inputs!$F$49 | E10: =IF(C10<=D10,"OK","ERROR") | L10: =ABS(Calculations!L128-Calculations!L119) | M10: =ABS(Calculations!M128-Calculations!M119) | N10: =ABS(Calculations!N128-Calculations!N119) | O10: =ABS(Calculations!O128-Calculations!O119) | P10: =ABS(Calculations!P128-Calculations!P119)
B11: Initiatives' EBIT adds up to incremental EBIT (abs. difference) | C11: =MAX(L11:P11) | D11: =Inputs!$F$49 | E11: =IF(C11<=D11,"OK","ERROR") | L11: =ABS(Calculations!L156-Calculations!L160) | M11: =ABS(Calculations!M156-Calculations!M160) | N11: =ABS(Calculations!N156-Calculations!N160) | O11: =ABS(Calculations!O156-Calculations!O160) | P11: =ABS(Calculations!P156-Calculations!P160)
B12: Pillars add up to initiatives (abs. difference) | C12: =MAX(L12:P12) | D12: =Inputs!$F$49 | E12: =IF(C12<=D12,"OK","ERROR") | L12: =ABS(Calculations!L134-Calculations!L128) | M12: =ABS(Calculations!M134-Calculations!M128) | N12: =ABS(Calculations!N134-Calculations!N128) | O12: =ABS(Calculations!O134-Calculations!O128) | P12: =ABS(Calculations!P134-Calculations!P128)
B13: Target = baseline + incremental (abs. difference) | C13: =MAX(L13:P13) | D13: =Inputs!$F$49 | E13: =IF(C13<=D13,"OK","ERROR") | L13: =ABS(Calculations!L118-Calculations!L117-Calculations!L119) | M13: =ABS(Calculations!M118-Calculations!M117-Calculations!M119) | N13: =ABS(Calculations!N118-Calculations!N117-Calculations!N119) | O13: =ABS(Calculations!O118-Calculations!O117-Calculations!O119) | P13: =ABS(Calculations!P118-Calculations!P117-Calculations!P119)
B14: Base case vs history: baseline revenue CAGR inside the historical band (Calculations 9b) | C14: =Calculations!$E$194 | D14: =Calculations!$E$196 | E14: =IF(AND(C14>=Calculations!$E$195,C14<=D14),"OK","ERROR")
B15: Bridge closes: baseline + steps = target (abs. difference) | C15: =ABS(Bridge!C5+SUM(Bridge!C6:C8)-Bridge!C9) | D15: =Inputs!$F$49 | E15: =IF(C15<=D15,"OK","ERROR")
B16: EBIT bridge closes: steps = incremental EBIT (abs. difference) | C16: =ABS(Bridge!C12+SUM(Bridge!C13:C15)-Bridge!C16) | D16: =Inputs!$F$49 | E16: =IF(C16<=D16,"OK","ERROR")
B17: Objectives: strategies add up to the change in Revenue | C17: =ABS(Objectives!D14-Calculations!$E$211) | D17: =Inputs!$F$49 | E17: =IF(C17<=D17,"OK","ERROR")
B18: Objectives: pillars add up to the change in Revenue | C18: =ABS(Objectives!D21-Calculations!$E$211) | D18: =Inputs!$F$49 | E18: =IF(C18<=D18,"OK","ERROR")
B19: Objectives: strategies add up to the change in EBITDA | C19: =ABS(Objectives!E14-Calculations!$E$215) | D19: =Inputs!$F$49 | E19: =IF(C19<=D19,"OK","ERROR")
B20: Objectives: pillars add up to the change in EBITDA | C20: =ABS(Objectives!E21-Calculations!$E$215) | D20: =Inputs!$F$49 | E20: =IF(C20<=D20,"OK","ERROR")
B21: Frameworks: '1. Triple bottom line (Elkington)' adds up to the change in Revenue | C21: =ABS(Frameworks!D10-Calculations!$E$211) | D21: =Inputs!$F$49 | E21: =IF(C21<=D21,"OK","ERROR")
B22: Frameworks: '1. Triple bottom line (Elkington)' adds up to the change in EBITDA | C22: =ABS(Frameworks!E10-Calculations!$E$215) | D22: =Inputs!$F$49 | E22: =IF(C22<=D22,"OK","ERROR")
B23: Frameworks: '3. Ansoff matrix' adds up to the change in Revenue | C23: =ABS(Frameworks!D32-Calculations!$E$211) | D23: =Inputs!$F$49 | E23: =IF(C23<=D23,"OK","ERROR")
B24: Frameworks: '3. Ansoff matrix' adds up to the change in EBITDA | C24: =ABS(Frameworks!E32-Calculations!$E$215) | D24: =Inputs!$F$49 | E24: =IF(C24<=D24,"OK","ERROR")
B25: Frameworks: '4. Marketing mix (4Ps)' adds up to the change in Revenue | C25: =ABS(Frameworks!D44-Calculations!$E$211) | D25: =Inputs!$F$49 | E25: =IF(C25<=D25,"OK","ERROR")
B26: Frameworks: '4. Marketing mix (4Ps)' adds up to the change in EBITDA | C26: =ABS(Frameworks!E44-Calculations!$E$215) | D26: =Inputs!$F$49 | E26: =IF(C26<=D26,"OK","ERROR")
B27: Frameworks: '5. Value chain (Porter)' adds up to the change in Revenue | C27: =ABS(Frameworks!D60-Calculations!$E$211) | D27: =Inputs!$F$49 | E27: =IF(C27<=D27,"OK","ERROR")
B28: Frameworks: '5. Value chain (Porter)' adds up to the change in EBITDA | C28: =ABS(Frameworks!E60-Calculations!$E$215) | D28: =Inputs!$F$49 | E28: =IF(C28<=D28,"OK","ERROR")
B29: Frameworks: profitability tree adds up to the change in EBITDA | C29: =ABS(Frameworks!C21-Calculations!$E$215) | D29: =Inputs!$F$49 | E29: =IF(C29<=D29,"OK","ERROR")
B30: Penetration never exceeds 100% of the addressable market | C30: =MAX(Calculations!K85:P85) | D30: <= 100% | E30: =IF(C30<=1,"OK","ERROR")
B31: No driver goes negative | C31: =MIN(Calculations!K83:P83,Calculations!K93:P93,Calculations!K101:P101) | D31: >= 0 | E31: =IF(C31>=0,"OK","ERROR")
B32: Register: low <= base <= high on every row (count of breaks) | C32: =SUMPRODUCT((Inputs!E6:E53>Inputs!F6:F53)*1)+SUMPRODUCT((Inputs!F6:F53>Inputs!G6:G53)*1) | D32: 0 | E32: =IF(C32=0,"OK","ERROR")
B33: Register: every input has a source and a grade (count missing) | C33: =SUMPRODUCT((Inputs!F6:F53<>"")*(Inputs!I6:I53=""))+SUMPRODUCT((Inputs!F6:F53<>"")*(Inputs!L6:L53="")) | D33: 0 | E33: =IF(C33=0,"OK","ERROR")
B34: Register: uplifts above the reference-class upper quartile have a written justification (count missing) | C34: =SUMPRODUCT((Inputs!D6:D53="uplift")*(Inputs!F6:F53>Inputs!O6:O53)*(Inputs!Q6:Q53="")) | D34: 0 | E34: =IF(C34=0,"OK","ERROR")
B35: Initiative NPVs add up to the strategy NPV (abs. difference) | C35: =ABS(Calculations!$E$186-Calculations!$E$172) | D35: =Inputs!$F$49 | E35: =IF(C35<=D35,"OK","ERROR")
B36: WACC above terminal growth (Gordon model valid) | C36: =Calculations!$E$74-Calculations!$E$65 | D36: > 0 | E36: =IF(C36>0,"OK","ERROR")
B37: Scenarios ordered: NPV low <= base <= high | C37: =IF(AND(Sensitivity!$D$16<=Sensitivity!$D$17,Sensitivity!$D$17<=Sensitivity!$D$18),0,1) | D37: 0 | E37: =IF(C37=0,"OK","ERROR")
B38: Controls neutral: scenario = Base, tornado off, no overrides (count set) | C38: =(Sensitivity!$E$5<>Sensitivity!$C$17)*1+(Sensitivity!$E$6<>0)*1+COUNT(Sensitivity!$E$7)+COUNT(Sensitivity!$E$8)+COUNT(Sensitivity!$E$9)+COUNT(Sensitivity!$E$10) | D38: 0 | E38: =IF(C38=0,"OK","ERROR")
B39: Max YoY growth of target revenue (must stay under the growth cap) | C39: =MAX(L39:P39) | D39: =Inputs!$F$47 | E39: =IF(C39<=D39,"OK","ERROR") | L39: =Calculations!L118/Calculations!K118-1 | M39: =Calculations!M118/Calculations!L118-1 | N39: =Calculations!N118/Calculations!M118-1 | O39: =Calculations!O118/Calculations!N118-1 | P39: =Calculations!P118/Calculations!O118-1

Sheet Driver tree
B1: Driver tree
B2: Every leaf is measurable and has one owning initiative or an explicit split rule.
B4: Target metric: incremental revenue growth (EURm), 2025-2029 vs do-nothing
B5: Revenue stream: Core revenue = Customers x Purchases per customer x Average ticket x Unit conversion: EUR to EURm with customers in millions
B6: Leaf: Customers [m] - owner: Initiative A1 - split: single owner - measured by: History: last reported value of Customers (reported) 2020-2024 (live link to the Actuals sheet). Data: ILLUSTRATIVE - replace (annual report KPIs / case pack)
B7: Initiative: Initiative A1 (a) - Raise customers
B8: Leaf: Purchases per customer [x] - owner: Initiative B1 - split: single owner - measured by: ILLUSTRATIVE - replace (loyalty data)
B9: Initiative: Initiative B1 (b) - Raise purchase frequency
B10: Leaf: Average ticket [EUR] - owner: Initiative C1 - split: single owner - measured by: Derived: revenue / (customers x purchases)
B11: Initiative: Initiative C1 (c) - Raise average ticket
B12: Costs: initiative opex and capex (quantity x unit cost where given); incremental EBIT = incremental revenue x margin + cost savings - opex
B13: Cash: FCF = EBIT x (1 - tax) - capex, discounted at WACC = E/V x (rf + beta x ERP + CRP) + D/V x kd x (1 - tax)

Sheet Data requests
B1: Data Request Sheet
B2: Pull each licensed item from the IE library, export with the exact file name, upload it, and Claude updates the Inputs row.
A4: Who | B4: Needed for (input) | C4: Database / source | D4: Exact table, report or URL | E4: Filters | F4: Years | G4: Export as (file name) | H4: Owner | I4: Status | J4: Route | K4: Manual fallback
A5: Team pulls (IE library) | B5: rev - Revenue (reported) | C5: SABI | D5: Company > Cuentas > Cuenta de perdidas y ganancias | E5: Individual, EUR thousands | F5: 2020-2024 | G5: sabi_example_pl_2020_2024.xlsx | I5: open | J5: Browser agent (supervised), else team manual export | K5: Log in to SABI through the IE library portal, apply the filters, export as sabi_example_pl_2020_2024.xlsx, upload it; until then the provisional value stays (see grade)
